<?xml version="1.0" ?>
<robot name="martha" xmlns:xacro="http://www.ros.org/wiki/xacro">

<xacro:include filename="$(find martha_description)/urdf/materials.xacro" />
<xacro:include filename="$(find martha_description)/urdf/martha.trans" />
<xacro:include filename="$(find martha_description)/urdf/martha.gazebo" />
<xacro:include filename="$(find martha_description)/urdf/camera.xacro" />
<xacro:include filename="$(find martha_description)/urdf/IMU.xacro" />
<link name="base_link">
  <inertial>
    <origin xyz="-0.00023301230905643097 -0.008767749720889163 0.08499100214486582" rpy="0 0 0"/>
    <mass value="3.42324299"/>
    <inertia 	ixx="0.03329076"	ixy="0.00032536"	ixz="0.00003330"
	            iyx="0.00032536"	iyy="0.01155302"	iyz="0.00085085"
	            izx="0.00003330"	izy="0.00085085"	izz="0.03581659"/>
  </inertial>
  <visual>
    <origin xyz="0 0 0" rpy="0 0 0"/>
    <geometry>
      <mesh filename="package://martha_description/meshes/base_link.stl" scale="0.001 0.001 0.001"/>
    </geometry>
    <material name="silver"/>
  </visual>
  <collision>
    <origin xyz="0 0 0" rpy="0 0 0"/>
    <geometry>
      <mesh filename="package://martha_description/meshes/base_link.stl" scale="0.001 0.001 0.001"/>
    </geometry>
  </collision>
</link>

<link name="pescoco_1">
  <inertial>
    <origin xyz="-1.9023224968807838e-14 -8.281569874313277e-15 0.011104750965744897" rpy="0 0 0"/>
    <mass value="0.00752807"/>
    <inertia ixx="0.00000284"	  ixy="0.0"	        ixz="-0.00000089"
	           iyx="0.0"	        iyy="0.00000317"	iyz="0.0"
	           izx="-0.00000089"	izy="0.0"	        izz="0.00000445"/>
  </inertial>
  <visual>
    <origin xyz="0.0 0.0114 -0.191473" rpy="0 0 0"/>
    <geometry>
      <mesh filename="package://martha_description/meshes/pescoco_1.stl" scale="0.001 0.001 0.001"/>
    </geometry>
    <material name="silver"/>
  </visual>
  <collision>
    <origin xyz="0.0 0.0114 -0.191473" rpy="0 0 0"/>
    <geometry>
      <mesh filename="package://martha_description/meshes/pescoco_1.stl" scale="0.001 0.001 0.001"/>
    </geometry>
  </collision>
</link>

<link name="cabeca_1">
  <inertial>
    <origin xyz="-0.020728139217007956 -0.025090240858054468 0.029326950387914386" rpy="0 0 0"/>
    <mass value="0.16989203"/>
    <inertia ixx="0.00036883"	  ixy="0.00001840"	ixz="-0.00000236"
	           iyx="0.00001840"	  iyy="0.00015387"	iyz="-0.00010413"
	           izx="-0.00000236"	izy="-0.00010413"	izz="0.00024492"/>
  </inertial>
  <visual>
    <origin xyz="-0.021 0.0114 -0.220473" rpy="0 0 0"/>
    <geometry>
      <mesh filename="package://martha_description/meshes/cabeca_1.stl" scale="0.001 0.001 0.001"/>
    </geometry>
    <material name="silver"/>
  </visual>
  <collision>
    <origin xyz="-0.021 0.0114 -0.220473" rpy="0 0 0"/>
    <geometry>
      <mesh filename="package://martha_description/meshes/cabeca_1.stl" scale="0.001 0.001 0.001"/>
    </geometry>
  </collision>
</link>

<link name="ombro_esquerdo_1">
  <inertial>
    <origin xyz="0.0066866699241785454 2.0816681711721685e-17 -0.0032002556517522762" rpy="0 0 0"/>
    <mass value="0.00784823"/>
    <inertia ixx="0.00000247"	  ixy="0.00000054"	ixz="-0.00000015"
	           iyx="0.00000054"	  iyy="0.00000437"	iyz="0.00000056"
	           izx="-0.00000015"	izy="0.00000056"	izz="0.00000374"/>
  </inertial>
  <visual>
    <origin xyz="-0.0771 0.01 -0.16273" rpy="0 0 0"/>
    <geometry>
      <mesh filename="package://martha_description/meshes/ombro_esquerdo_1.stl" scale="0.001 0.001 0.001"/>
    </geometry>
    <material name="silver"/>
  </visual>
  <collision>
    <origin xyz="-0.0771 0.01 -0.16273" rpy="0 0 0"/>
    <geometry>
      <mesh filename="package://martha_description/meshes/ombro_esquerdo_1.stl" scale="0.001 0.001 0.001"/>
    </geometry>
  </collision>
</link>

<link name="ombro_direito_1">
  <inertial>
    <origin xyz="-0.006686669924178101 2.7755575615628914e-17 -0.0032002556517522207" rpy="0 0 0"/>
    <mass value="0.00784823"/>
    <inertia ixx="0.00000247"	  ixy="0.00000054"	ixz="-0.00000015"
	           iyx="0.00000054"	  iyy="0.00000437"	iyz="0.00000056"
	           izx="-0.00000015"	izy="0.00000056"	izz="0.00000374"/>
  </inertial>
  <visual>
    <origin xyz="0.0771 0.01 -0.16273" rpy="0 0 0"/>
    <geometry>
      <mesh filename="package://martha_description/meshes/ombro_direito_1.stl" scale="0.001 0.001 0.001"/>
    </geometry>
    <material name="silver"/>
  </visual>
  <collision>
    <origin xyz="0.0771 0.01 -0.16273" rpy="0 0 0"/>
    <geometry>
      <mesh filename="package://martha_description/meshes/ombro_direito_1.stl" scale="0.001 0.001 0.001"/>
    </geometry>
  </collision>
</link>

<link name="braco_esquerdo_1">
  <inertial>
    <origin xyz="2.1478896477855614e-05 0.020766946865101756 -0.04944488755371944" rpy="0 0 0"/>
    <mass value="0.24511984"/>
    <inertia ixx="0.00115082"	  ixy="-0.00004952"	ixz="-0.00001482"
	           iyx="-0.00004952"	iyy="0.00018286"	iyz="0.00028731"
	           izx="-0.00001482"	izy="0.00028731"	izz="0.00101703"/>
  </inertial>
  <visual>
    <origin xyz="-0.0971 0.031 -0.14823" rpy="0 0 0"/>
    <geometry>
      <mesh filename="package://martha_description/meshes/braco_esquerdo_1.stl" scale="0.001 0.001 0.001"/>
    </geometry>
    <material name="silver"/>
  </visual>
  <collision>
    <origin xyz="-0.0971 0.031 -0.14823" rpy="0 0 0"/>
    <geometry>
      <mesh filename="package://martha_description/meshes/braco_esquerdo_1.stl" scale="0.001 0.001 0.001"/>
    </geometry>
  </collision>
</link>

<link name="braco_direito_1">
  <inertial>
    <origin xyz="2.1478896478493992e-05 0.02076694686510183 -0.04944488755371926" rpy="0 0 0"/>
    <mass value="0.24511984"/>
    <inertia ixx="0.00115082"	  ixy="-0.00004952"	ixz="-0.00001482"
	           iyx="-0.00004952"	iyy="0.00018286"	iyz="0.00028731"
	           izx="-0.00001482"	izy="0.00028731"	izz="0.00101703"/>
  </inertial>
  <visual>
    <origin xyz="0.0971 0.031 -0.14823" rpy="0 0 0"/>
    <geometry>
      <mesh filename="package://martha_description/meshes/braco_direito_1.stl" scale="0.001 0.001 0.001"/>
    </geometry>
    <material name="silver"/>
  </visual>
  <collision>
    <origin xyz="0.0971 0.031 -0.14823" rpy="0 0 0"/>
    <geometry>
      <mesh filename="package://martha_description/meshes/braco_direito_1.stl" scale="0.001 0.001 0.001"/>
    </geometry>
  </collision>
</link>

<link name="mao_esquerda_1">
  <inertial>
    <origin xyz="0.0009999999999996262 1.8780116350924914e-14 -0.051558141367889714" rpy="0 0 0"/>
    <mass value="0.00500432"/>
    <inertia ixx="0.00001624"	  ixy="-0.00000647"	ixz="-0.00000010"
	           iyx="-0.00000647"	iyy="0.00000281"	iyz="0.00000024"
	           izx="-0.00000010"	izy="0.00000024"	izz="0.00001904"/>
  </inertial>
  <visual>
    <origin xyz="-0.11785 0.01026 -0.04863" rpy="0 0 0"/>
    <geometry>
      <mesh filename="package://martha_description/meshes/mao_esquerda_1.stl" scale="0.001 0.001 0.001"/>
    </geometry>
    <material name="silver"/>
  </visual>
  <collision>
    <origin xyz="-0.11785 0.01026 -0.04863" rpy="0 0 0"/>
    <geometry>
      <mesh filename="package://martha_description/meshes/mao_esquerda_1.stl" scale="0.001 0.001 0.001"/>
    </geometry>
  </collision>
</link>

<link name="mao_direita_1">
  <inertial>
    <origin xyz="-0.0009999999999998066 -1.917389857997165e-14 -0.05155814136788935" rpy="0 0 0"/>
    <mass value="0.00500432"/>
    <inertia ixx="0.00001624"	  ixy="-0.00000647"	ixz="-0.00000010"
	           iyx="-0.00000647"	iyy="0.00000281"	iyz="0.00000024"
	           izx="-0.00000010"	izy="0.00000024"	izz="0.00001904"/>
  </inertial>
  <visual>
    <origin xyz="0.11785 0.01026 -0.04863" rpy="0 0 0"/>
    <geometry>
      <mesh filename="package://martha_description/meshes/mao_direita_1.stl" scale="0.001 0.001 0.001"/>
    </geometry>
    <material name="silver"/>
  </visual>
  <collision>
    <origin xyz="0.11785 0.01026 -0.04863" rpy="0 0 0"/>
    <geometry>
      <mesh filename="package://martha_description/meshes/mao_direita_1.stl" scale="0.001 0.001 0.001"/>
    </geometry>
  </collision>
</link>

<link name="quadril_esquerdo_1">
  <inertial>
    <origin xyz="1.4314938123760612e-14 0.001988067036543086 -0.01689495335095707" rpy="0 0 0"/>
    <mass value="0.00770492"/>
    <inertia ixx="0.00000604"	ixy="0.0"	        ixz="0.0"
	           iyx="0.0"	      iyy="0.00000333"	iyz="0.00000005"
	           izx="0.0"	      izy="0.00000005"	izz="0.00000335"/>
  </inertial>
  <visual>
    <origin xyz="-0.04 0.01 0.0044" rpy="0 0 0"/>
    <geometry>
      <mesh filename="package://martha_description/meshes/quadril_esquerdo_1.stl" scale="0.001 0.001 0.001"/>
    </geometry>
    <material name="silver"/>
  </visual>
  <collision>
    <origin xyz="-0.04 0.01 0.0044" rpy="0 0 0"/>
    <geometry>
      <mesh filename="package://martha_description/meshes/quadril_esquerdo_1.stl" scale="0.001 0.001 0.001"/>
    </geometry>
  </collision>
</link>

<link name="coxa_esquerda_1">
  <inertial>
    <origin xyz="1.4332694612498309e-05 -0.0006782563173738359 -0.01214207998264017" rpy="0 0 0"/>
    <mass value="0.09798763"/>
    <inertia ixx="0.00011704"	  ixy="-0.00002470"	ixz="-0.00004285"
	           iyx="-0.00002470"	iyy="0.00015120"	iyz="0.00001970"
	           izx="-0.00004285"	izy="0.00001970"	izz="0.00009318"/>
  </inertial>
  <visual>
    <origin xyz="-0.04 -0.01215 0.0399" rpy="0 0 0"/>
    <geometry>
      <mesh filename="package://martha_description/meshes/coxa_esquerda_1.stl" scale="0.001 0.001 0.001"/>
    </geometry>
    <material name="silver"/>
  </visual>
  <collision>
    <origin xyz="-0.04 -0.01215 0.0399" rpy="0 0 0"/>
    <geometry>
      <mesh filename="package://martha_description/meshes/coxa_esquerda_1.stl" scale="0.001 0.001 0.001"/>
    </geometry>
  </collision>
</link>

<link name="canela_esquerda_2_1">
  <inertial>
    <origin xyz="0.02210055083330358 -0.004367378251287552 -0.05012443509922551" rpy="0 0 0"/>
    <mass value="0.00914336"/>
    <inertia ixx="0.00004108"	  ixy="-0.00001063"	ixz="-0.00000087"
	           iyx="-0.00001063"	iyy="0.00000815"	iyz="0.00000285"
	           izx="-0.00000087"	izy="0.00000285"	izz="0.00004741"/>
  </inertial>
  <visual>
    <origin xyz="-0.01975 0.0073 0.1404" rpy="0 0 0"/>
    <geometry>
      <mesh filename="package://martha_description/meshes/canela_esquerda_2_1.stl" scale="0.001 0.001 0.001"/>
    </geometry>
    <material name="silver"/>
  </visual>
  <collision>
    <origin xyz="-0.01975 0.0073 0.1404" rpy="0 0 0"/>
    <geometry>
      <mesh filename="package://martha_description/meshes/canela_esquerda_2_1.stl" scale="0.001 0.001 0.001"/>
    </geometry>
  </collision>
</link>

<link name="canela_esquerda_1">
  <inertial>
    <origin xyz="0.0228493411868047 -2.7628101325824495e-09 -0.07781833032204813" rpy="0 0 0"/>
    <mass value="0.05533250"/>
    <inertia ixx="0.00035394"	ixy="0.00009305"	ixz="0.00000038"
	           iyx="0.00009305"	iyy="0.00003922"	iyz="0.00000131"
	           izx="0.00000038"	izy="0.00000131"	izz="0.00038649"/>
  </inertial>
  <visual>
    <origin xyz="-0.0174 0.0073 0.0399" rpy="0 0 0"/>
    <geometry>
      <mesh filename="package://martha_description/meshes/canela_esquerda_1.stl" scale="0.001 0.001 0.001"/>
    </geometry>
    <material name="silver"/>
  </visual>
  <collision>
    <origin xyz="-0.0174 0.0073 0.0399" rpy="0 0 0"/>
    <geometry>
      <mesh filename="package://martha_description/meshes/canela_esquerda_1.stl" scale="0.001 0.001 0.001"/>
    </geometry>
  </collision>
</link>

<link name="calcanhar_esquerdo_1">
  <inertial>
    <origin xyz="-0.022614332694585237 0.018771743681580518 0.012142498757541087" rpy="0 0 0"/>
    <mass value="0.09643869"/>
    <inertia ixx="0.00011593"	  ixy="-0.00002082"	ixz="-0.00004182"
	           iyx="-0.00002082"	iyy="0.00014789"	iyz="0.00001782"
	           izx="-0.00004182"	izy="0.00001782"	izz="0.00008568"/>
  </inertial>
  <visual>
    <origin xyz="-0.0631 0.0073 0.240425" rpy="0 0 0"/>
    <geometry>
      <mesh filename="package://martha_description/meshes/calcanhar_esquerdo_1.stl" scale="0.001 0.001 0.001"/>
    </geometry>
    <material name="silver"/>
  </visual>
  <collision>
    <origin xyz="-0.0631 0.0073 0.240425" rpy="0 0 0"/>
    <geometry>
      <mesh filename="package://martha_description/meshes/calcanhar_esquerdo_1.stl" scale="0.001 0.001 0.001"/>
    </geometry>
  </collision>
</link>

<link name="pe_esquerdo_1">
  <inertial>
    <origin xyz="0.0034112806849335223 -0.026374357215448188 -0.035772752451398604" rpy="0 0 0"/>
    <mass value="0.04184724"/>
    <inertia ixx="0.00013469"	ixy="0.00000867"	ixz="0.00000565"
	           iyx="0.00000867"	iyy="0.00007646"	iyz="0.00004294"
	           izx="0.00000565"	izy="0.00004294"	izz="0.00008670"/>
    </inertial>
  <visual>
    <origin xyz="-0.0405 -0.01215 0.240425" rpy="0 0 0"/>
    <geometry>
      <mesh filename="package://martha_description/meshes/pe_esquerdo_1.stl" scale="0.001 0.001 0.001"/>
    </geometry>
    <material name="silver"/>
  </visual>
  <collision>
    <origin xyz="-0.0405 -0.01215 0.240425" rpy="0 0 0"/>
    <geometry>
      <mesh filename="package://martha_description/meshes/pe_esquerdo_1.stl" scale="0.001 0.001 0.001"/>
    </geometry>
  </collision>
</link>

<link name="pe_direito_1">
  <inertial>
    <origin xyz="-0.003474406179630303 -0.025760560273646108 -0.03643473231799649" rpy="0 0 0"/>
    <mass value="0.04184724"/>
    <inertia ixx="0.00013469"	ixy="0.00000867"	ixz="0.00000565"
	           iyx="0.00000867"	iyy="0.00007646"	iyz="0.00004294"
	           izx="0.00000565"	izy="0.00004294"	izz="0.00008670"/>
    </inertial>
  <visual>
    <origin xyz="0.0395 -0.01215 0.240425" rpy="0 0 0"/>
    <geometry>
      <mesh filename="package://martha_description/meshes/pe_direito_1.stl" scale="0.001 0.001 0.001"/>
    </geometry>
    <material name="silver"/>
  </visual>
  <collision>
    <origin xyz="0.0395 -0.01215 0.240425" rpy="0 0 0"/>
    <geometry>
      <mesh filename="package://martha_description/meshes/pe_direito_1.stl" scale="0.001 0.001 0.001"/>
    </geometry>
  </collision>
</link>

<link name="calcanhar_direito_1">
  <inertial>
    <origin xyz="-0.022614332694585272 0.018771743681580518 0.012142498757541087" rpy="0 0 0"/>
    <mass value="0.09643869"/>
    <inertia ixx="0.00011593"	  ixy="-0.00002082"	ixz="-0.00004182"
	           iyx="-0.00002082"	iyy="0.00014789"	iyz="0.00001782"
	           izx="-0.00004182"	izy="0.00001782"	izz="0.00008568"/>
  </inertial>
  <visual>
    <origin xyz="0.0169 0.0073 0.240425" rpy="0 0 0"/>
    <geometry>
      <mesh filename="package://martha_description/meshes/calcanhar_direito_1.stl" scale="0.001 0.001 0.001"/>
    </geometry>
    <material name="silver"/>
  </visual>
  <collision>
    <origin xyz="0.0169 0.0073 0.240425" rpy="0 0 0"/>
    <geometry>
      <mesh filename="package://martha_description/meshes/calcanhar_direito_1.stl" scale="0.001 0.001 0.001"/>
    </geometry>
  </collision>
</link>

<link name="canela_direita_2_1">
  <inertial>
    <origin xyz="0.022100550833303534 -0.004367378251287554 -0.05012443509922543" rpy="0 0 0"/>
    <mass value="0.00914336"/>
    <inertia ixx="0.00004108"	  ixy="-0.00001063"	ixz="-0.00000087"
	           iyx="-0.00001063"	iyy="0.00000815"	iyz="0.00000285"
	           izx="-0.00000087"	izy="0.00000285"	izz="0.00004741"/>
  </inertial>
  <visual>
    <origin xyz="0.06025 0.0073 0.1404" rpy="0 0 0"/>
    <geometry>
      <mesh filename="package://martha_description/meshes/canela_direita_2_1.stl" scale="0.001 0.001 0.001"/>
    </geometry>
    <material name="silver"/>
  </visual>
  <collision>
    <origin xyz="0.06025 0.0073 0.1404" rpy="0 0 0"/>
    <geometry>
      <mesh filename="package://martha_description/meshes/canela_direita_2_1.stl" scale="0.001 0.001 0.001"/>
    </geometry>
  </collision>
</link>

<link name="canela_direita_1">
  <inertial>
    <origin xyz="0.02284934118680465 -2.76281013778662e-09 -0.07781833032204813" rpy="0 0 0"/>
    <mass value="0.05533250"/>
    <inertia ixx="0.00035394"	ixy="0.00009305"	ixz="0.00000038"
	           iyx="0.00009305"	iyy="0.00003922"	iyz="0.00000131"
	           izx="0.00000038"	izy="0.00000131"	izz="0.00038649"/>
  </inertial>
  <visual>
    <origin xyz="0.0626 0.0073 0.0399" rpy="0 0 0"/>
    <geometry>
      <mesh filename="package://martha_description/meshes/canela_direita_1.stl" scale="0.001 0.001 0.001"/>
    </geometry>
    <material name="silver"/>
  </visual>
  <collision>
    <origin xyz="0.0626 0.0073 0.0399" rpy="0 0 0"/>
    <geometry>
      <mesh filename="package://martha_description/meshes/canela_direita_1.stl" scale="0.001 0.001 0.001"/>
    </geometry>
  </collision>
</link>

<link name="coxa_direita_1">
  <inertial>
    <origin xyz="1.4332694612477492e-05 -0.0006782563173738359 -0.01214207998264017" rpy="0 0 0"/>
    <mass value="0.09798763"/>
    <inertia ixx="0.00011704"	  ixy="-0.00002470"	ixz="-0.00004285"
	           iyx="-0.00002470"	iyy="0.00015120"	iyz="0.00001970"
	           izx="-0.00004285"	izy="0.00001970"	izz="0.00009318"/>
  </inertial>
  <visual>
    <origin xyz="0.04 -0.01215 0.0399" rpy="0 0 0"/>
    <geometry>
      <mesh filename="package://martha_description/meshes/coxa_direita_1.stl" scale="0.001 0.001 0.001"/>
    </geometry>
    <material name="silver"/>
  </visual>
  <collision>
    <origin xyz="0.04 -0.01215 0.0399" rpy="0 0 0"/>
    <geometry>
      <mesh filename="package://martha_description/meshes/coxa_direita_1.stl" scale="0.001 0.001 0.001"/>
    </geometry>
  </collision>
</link>


<link name="quadril_direito_1">
  <inertial>
    <origin xyz="1.4287182548144983e-14 0.0019880670365430807 -0.016894953350957066" rpy="0 0 0"/>
    <mass value="0.00770492"/>
    <inertia ixx="0.00000604"	ixy="0.0"	        ixz="0.0"
	           iyx="0.0"	      iyy="0.00000333"	iyz="0.00000005"
	           izx="0.0"	      izy="0.00000005"	izz="0.00000335"/>
  </inertial>
  <visual>
    <origin xyz="0.04 0.01 0.0044" rpy="0 0 0"/>
    <geometry>
      <mesh filename="package://martha_description/meshes/quadril_direito_1.stl" scale="0.001 0.001 0.001"/>
    </geometry>
    <material name="silver"/>
  </visual>
  <collision>
    <origin xyz="0.04 0.01 0.0044" rpy="0 0 0"/>
    <geometry>
      <mesh filename="package://martha_description/meshes/quadril_direito_1.stl" scale="0.001 0.001 0.001"/>
    </geometry>
  </collision>
</link>

<joint name="pescoco_rZ" type="continuous">
  <origin xyz="0.0 -0.0114 0.191473" rpy="0 0 0"/>
  <parent link="base_link"/>
  <child link="pescoco_1"/>
  <axis xyz="-0.0 -0.0 1.0"/>
  <limit effort="1000.0" velocity="0.01"/>
</joint>

<joint name="cabeca_rX" type="continuous">
  <origin xyz="0.021 0.0 0.029" rpy="0 0 0"/>
  <parent link="pescoco_1"/>
  <child link="cabeca_1"/>
  <axis xyz="1.0 -0.0 0.0"/>
  <limit effort="1000.0" velocity="0.01"/>
</joint>

<joint name="ombro_esquerdo_rX" type="continuous">
  <origin xyz="0.0771 -0.01 0.16273" rpy="0 0 0"/>
  <parent link="base_link"/>
  <child link="ombro_esquerdo_1"/>
  <axis xyz="1.0 0.0 -0.0"/>
  <limit effort="1000.0" velocity="0.01"/>
</joint>

<joint name="ombro_direito_rX" type="continuous">
  <origin xyz="-0.0771 -0.01 0.16273" rpy="0 0 0"/>
  <parent link="base_link"/>
  <child link="ombro_direito_1"/>
  <axis xyz="-1.0 -0.0 0.0"/>
  <limit effort="1000.0" velocity="0.01"/>
</joint>

<joint name="ombro_esquerdo_rY" type="continuous">
  <origin xyz="0.02 -0.021 -0.0145" rpy="0 0 0"/>
  <parent link="ombro_esquerdo_1"/>
  <child link="braco_esquerdo_1"/>
  <axis xyz="0.0 -1.0 0.0"/>
  <limit effort="1000.0" velocity="0.01"/>
</joint>

<joint name="ombro_direito_rY" type="continuous">
  <origin xyz="-0.02 -0.021 -0.0145" rpy="0 0 0"/>
  <parent link="ombro_direito_1"/>
  <child link="braco_direito_1"/>
  <axis xyz="0.0 -1.0 -0.0"/>
  <limit effort="1000.0" velocity="0.01"/>
</joint>

<joint name="mao_esquerda" type="continuous">
  <origin xyz="0.02075 0.02074 -0.0996" rpy="0 0 0"/>
  <parent link="braco_esquerdo_1"/>
  <child link="mao_esquerda_1"/>
  <axis xyz="1.0 0.0 -0.0"/>
  <limit effort="1000.0" velocity="0.01"/>
</joint>

<joint name="mao_direita" type="continuous">
  <origin xyz="-0.02075 0.02074 -0.0996" rpy="0 0 0"/>
  <parent link="braco_direito_1"/>
  <child link="mao_direita_1"/>
  <axis xyz="1.0 0.0 -0.0"/>
  <limit effort="1000.0" velocity="0.01"/>
</joint>

<joint name="quadril_esquerdo_rZ" type="continuous">
  <origin xyz="0.04 -0.01 -0.0044" rpy="0 0 0"/>
  <parent link="base_link"/>
  <child link="quadril_esquerdo_1"/>
  <axis xyz="0.0 0.0 -1.0"/>
  <limit effort="1000.0" velocity="0.01"/>
</joint>

<joint name="quadril_esquerdo_rY" type="continuous">
  <origin xyz="0.0 0.02215 -0.0355" rpy="0 0 0"/>
  <parent link="quadril_esquerdo_1"/>
  <child link="coxa_esquerda_1"/>
  <axis xyz="0.0 -1.0 -0.0"/>
  <limit effort="1000.0" velocity="0.01"/>
</joint>

<joint name="joelho_esquerdo_rX" type="continuous">
  <origin xyz="0.00235 0.0 -0.1005" rpy="0 0 0"/>
  <parent link="canela_esquerda_1"/>
  <child link="canela_esquerda_2_1"/>
  <axis xyz="-1.0 -0.0 -0.0"/>
  <limit effort="1000.0" velocity="0.01"/>
</joint>

<joint name="quadril_esquerdo_rX" type="continuous">
  <origin xyz="-0.0226 -0.01945 0.0" rpy="0 0 0"/>
  <parent link="coxa_esquerda_1"/>
  <child link="canela_esquerda_1"/>
  <axis xyz="1.0 0.0 0.0"/>
  <limit effort="1000.0" velocity="0.01"/>
</joint>

<joint name="tornozelo_esquerdo_rX" type="continuous">
  <origin xyz="0.04335 0.0 -0.100025" rpy="0 0 0"/>
  <parent link="canela_esquerda_2_1"/>
  <child link="calcanhar_esquerdo_1"/>
  <axis xyz="1.0 0.0 0.0"/>
  <limit effort="1000.0" velocity="0.01"/>
</joint>

<joint name="tornozelo_esquerdo_rY" type="continuous">
  <origin xyz="-0.0226 0.01945 0.0" rpy="0 0 0"/>
  <parent link="calcanhar_esquerdo_1"/>
  <child link="pe_esquerdo_1"/>
  <axis xyz="-0.0 1.0 0.0"/>
  <limit effort="1000.0" velocity="0.01"/>
</joint>

<joint name="tornozelo_direito_rY" type="continuous">
  <origin xyz="-0.0226 0.01945 0.0" rpy="0 0 0"/>
  <parent link="calcanhar_direito_1"/>
  <child link="pe_direito_1"/>
  <axis xyz="-0.0 1.0 0.0"/>
  <limit effort="1000.0" velocity="0.01"/>
</joint>

<joint name="tornozelo_direito_rX" type="continuous">
  <origin xyz="0.04335 0.0 -0.100025" rpy="0 0 0"/>
  <parent link="canela_direita_2_1"/>
  <child link="calcanhar_direito_1"/>
  <axis xyz="1.0 0.0 0.0"/>
  <limit effort="1000.0" velocity="0.01"/>
</joint>

<joint name="joelho_direito_rX" type="continuous">
  <origin xyz="0.00235 0.0 -0.1005" rpy="0 0 0"/>
  <parent link="canela_direita_1"/>
  <child link="canela_direita_2_1"/>
  <axis xyz="-1.0 -0.0 -0.0"/>
  <limit effort="1000.0" velocity="0.01"/>
</joint>

<joint name="quadril_direito_rX" type="continuous">
  <origin xyz="-0.0226 -0.01945 0.0" rpy="0 0 0"/>
  <parent link="coxa_direita_1"/>
  <child link="canela_direita_1"/>
  <axis xyz="1.0 0.0 0.0"/>
  <limit effort="1000.0" velocity="0.01"/>
</joint>

<joint name="quadril_direito_rY" type="continuous">
  <origin xyz="0.0 0.02215 -0.0355" rpy="0 0 0"/>
  <parent link="quadril_direito_1"/>
  <child link="coxa_direita_1"/>
  <axis xyz="0.0 -1.0 -0.0"/>
  <limit effort="1000.0" velocity="0.01"/>
</joint>

<joint name="quadril_direito_rZ" type="continuous">
  <origin xyz="-0.04 -0.01 -0.0044" rpy="0 0 0"/>
  <parent link="base_link"/>
  <child link="quadril_direito_1"/>
  <axis xyz="0.0 0.0 -1.0"/>
  <limit effort="1000.0" velocity="0.01"/>
</joint>

<joint name="base_link_to_pescoco_1" type="revolute">
  <parent link="base_link"/>
  <child link="pescoco_1"/>
  <origin xyz="0.0 -0.0114 0.191473" rpy="0 0 0"/>
  <axis xyz="-0.0 -0.0 1.0"/>
  <limit lower="-3.14159" upper="3.14159" effort="1000.0" velocity="0.01"/>
</joint>

<joint name="pescoco_1_to_cabeca_1" type="revolute">
  <parent link="pescoco_1"/>
  <child link="cabeca_1"/>
  <origin xyz="0.021 0.0 0.029" rpy="0 0 0"/>
  <axis xyz="1.0 -0.0 0.0"/>
  <limit lower="-3.14159" upper="3.14159" effort="1000.0" velocity="0.01"/>
</joint>

<joint name="base_link_to_ombro_esquerdo_1" type="revolute">
  <parent link="base_link"/>
  <child link="ombro_esquerdo_1"/>
  <origin xyz="0.0771 -0.01 0.16273" rpy="0 0 0"/>
  <axis xyz="1.0 0.0 -0.0"/>
  <limit lower="-3.14159" upper="3.14159" effort="1000.0" velocity="0.01"/>
</joint>

<joint name="base_link_to_ombro_direito_1" type="revolute">
  <parent link="base_link"/>
  <child link="ombro_direito_1"/>
  <origin xyz="-0.0771 -0.01 0.16273" rpy="0 0 0"/>
  <axis xyz="-1.0 -0.0 0.0"/>
  <limit lower="-3.14159" upper="3.14159" effort="1000.0" velocity="0.01"/>
</joint>

<joint name="ombro_esquerdo_1_to_braco_esquerdo_1" type="revolute">
  <parent link="ombro_esquerdo_1"/>
  <child link="braco_esquerdo_1"/>
  <origin xyz="0.02 -0.021 -0.0145" rpy="0 0 0"/>
  <axis xyz="0.0 -1.0 0.0"/>
  <limit lower="-3.14159" upper="3.14159" effort="1000.0" velocity="0.01"/>
</joint>

<joint name="ombro_direito_1_to_braco_direito_1" type="revolute">
  <parent link="ombro_direito_1"/>
  <child link="braco_direito_1"/>
  <origin xyz="-0.02 -0.021 -0.0145" rpy="0 0 0"/>
  <axis xyz="0.0 -1.0 -0.0"/>
  <limit lower="-3.14159" upper="3.14159" effort="1000.0" velocity="0.01"/>
</joint>

<joint name="braco_esquerdo_1_to_mao_esquerda_1" type="revolute">
  <parent link="braco_esquerdo_1"/>
  <child link="mao_esquerda_1"/>
  <origin xyz="0.02075 0.02074 -0.0996" rpy="0 0 0"/>
  <axis xyz="1.0 0.0 -0.0"/>
  <limit lower="-3.14159" upper="3.14159" effort="1000.0" velocity="0.01"/>
</joint>

<joint name="braco_direito_1_to_mao_direita_1" type="revolute">
  <parent link="braco_direito_1"/>
  <child link="mao_direita_1"/>
  <origin xyz="-0.02075 0.02074 -0.0996" rpy="0 0 0"/>
  <axis xyz="1.0 0.0 -0.0"/>
  <limit lower="-3.14159" upper="3.14159" effort="1000.0" velocity="0.01"/>
</joint>

<joint name="base_link_to_quadril_esquerdo_1" type="revolute">
  <parent link="base_link"/>
  <child link="quadril_esquerdo_1"/>
  <origin xyz="0.04 -0.01 -0.0044" rpy="0 0 0"/>
  <axis xyz="0.0 0.0 -1.0"/>
  <limit lower="-3.14159" upper="3.14159" effort="1000.0" velocity="0.01"/>
</joint>

<joint name="quadril_esquerdo_1_to_coxa_esquerda_1" type="revolute">
  <parent link="quadril_esquerdo_1"/>
  <child link="coxa_esquerda_1"/>
  <origin xyz="0.0 0.02215 -0.0355" rpy="0 0 0"/>
  <axis xyz="0.0 -1.0 -0.0"/>
  <limit lower="-3.14159" upper="3.14159" effort="1000.0" velocity="0.01"/>
</joint>

<joint name="canela_esquerda_1_to_canela_esquerda_2_1" type="revolute">
  <parent link="canela_esquerda_1"/>
  <child link="canela_esquerda_2_1"/>
  <origin xyz="0.00235 0.0 -0.1005" rpy="0 0 0"/>
  <axis xyz="-1.0 -0.0 -0.0"/>
  <limit lower="-3.14159" upper="3.14159" effort="1000.0" velocity="0.01"/>
</joint>

<joint name="coxa_esquerda_1_to_canela_esquerda_1" type="revolute">
  <parent link="coxa_esquerda_1"/>
  <child link="canela_esquerda_1"/>
  <origin xyz="-0.0226 -0.01945 0.0" rpy="0 0 0"/>
  <axis xyz="1.0 0.0 0.0"/>
  <limit lower="-3.14159" upper="3.14159" effort="1000.0" velocity="0.01"/>
</joint>

<joint name="canela_esquerda_2_1_to_calcanhar_esquerdo_1" type="revolute">
  <parent link="canela_esquerda_2_1"/>
  <child link="calcanhar_esquerdo_1"/>
  <origin xyz="0.04335 0.0 -0.100025" rpy="0 0 0"/>
  <axis xyz="1.0 0.0 0.0"/>
  <limit lower="-3.14159" upper="3.14159" effort="1000.0" velocity="0.01"/>
</joint>

<joint name="calcanhar_esquerdo_1_to_pe_esquerdo_1" type="revolute">
  <parent link="calcanhar_esquerdo_1"/>
  <child link="pe_esquerdo_1"/>
  <origin xyz="-0.0226 0.01945 0.0" rpy="0 0 0"/>
  <axis xyz="-0.0 1.0 0.0"/>
  <limit lower="-3.14159" upper="3.14159" effort="1000.0" velocity="0.01"/>
</joint>

<joint name="calcanhar_direito_1_to_pe_direito_1" type="revolute">
  <parent link="calcanhar_direito_1"/>
  <child link="pe_direito_1"/>
  <origin xyz="-0.0226 0.01945 0.0" rpy="0 0 0"/>
  <axis xyz="-0.0 1.0 0.0"/>
  <limit lower="-3.14159" upper="3.14159" effort="1000.0" velocity="0.01"/>
</joint>

<joint name="canela_direita_2_1_to_calcanhar_direito_1" type="revolute">
  <parent link="canela_direita_2_1"/>
  <child link="calcanhar_direito_1"/>
  <origin xyz="0.04335 0.0 -0.100025" rpy="0 0 0"/>
  <axis xyz="1.0 0.0 0.0"/>
  <limit lower="-3.14159" upper="3.14159" effort="1000.0" velocity="0.01"/>
</joint>

<joint name="canela_direita_1_to_canela_direita_2_1" type="revolute">
  <parent link="canela_direita_1"/>
  <child link="canela_direita_2_1"/>
  <origin xyz="0.00235 0.0 -0.1005" rpy="0 0 0"/>
  <axis xyz="-1.0 -0.0 -0.0"/>
  <limit lower="-3.14159" upper="3.14159" effort="1000.0" velocity="0.01"/>
</joint>

<joint name="coxa_direita_1_to_canela_direita_1" type="revolute">
  <parent link="coxa_direita_1"/>
  <child link="canela_direita_1"/>
  <origin xyz="-0.0226 -0.01945 0.0" rpy="0 0 0"/>
  <axis xyz="1.0 0.0 0.0"/>
  <limit lower="-3.14159" upper="3.14159" effort="1000.0" velocity="0.01"/>
</joint>

<joint name="quadril_direito_1_to_coxa_direita_1" type="revolute">
  <parent link="quadril_direito_1"/>
  <child link="coxa_direita_1"/>
  <origin xyz="0.0 0.02215 -0.0355" rpy="0 0 0"/>
  <axis xyz="0.0 -1.0 -0.0"/>
  <limit lower="-3.14159" upper="3.14159" effort="1000.0" velocity="0.01"/>
</joint>

<joint name="base_link_to_quadril_direito_1" type="revolute">
  <parent link="base_link"/>
  <child link="quadril_direito_1"/>
  <origin xyz="-0.04 -0.01 -0.0044" rpy="0 0 0"/>
  <axis xyz="0.0 0.0 -1.0"/>
  <limit lower="-3.14159" upper="3.14159" effort="1000.0" velocity="0.01"/>
</joint>

<xacro:imu_sensor parent="base_link" ns="martha" origin="0 0 0 0 0 0"/>

<xacro:camera_sensor parent="cabeca_1" camera_name="front_camera" ns="martha" origin="-0.02060 -0.050864 0.047202 0 0 -1.57"/>
</robot>
